Workbook

Sheet README
A1: WA BROADACRE FARM DEBT SERVICEABILITY ANALYSIS - MALLET RIDGE PASTORAL CO.
A2: Credit Assessment | $1.5M Machinery Facility | May 2026
A4: 1. PROJECT PURPOSE
A5: This model assesses the debt serviceability of a representative Western Australian broadacre cropping operation - Mallet Ridge Pastoral Co. - against a proposed $1.5 million term loan facility for machinery replacement. Using ABARES farm survey benchmark data for WA cropping farms (2017-18 to 2023-24), the model calculates DSCR under base case and three stress scenarios, and maps the full range of outcomes across a two-variable sensitivity table. The analysis is framed as a preliminary credit assessment for an agribusiness lending institution.
A6: DISCLAIMER: Mallet Ridge Pastoral Co. is a fictional entity created for illustrative purposes. All financial inputs are derived from publicly available ABARES benchmark data. This analysis does not constitute financial or investment advice.
A8: 2. HOW TO NAVIGATE THIS FILE
A9: Tab | B9: Description
A10: README | B10: This page - project purpose, navigation guide, data sources
A11: Assumptions | B11: All model inputs - sourced, tiered by data quality, dated. Change inputs here only.
A12: Farm_Profile | B12: Mallet Ridge farm profile and ABARES time series data 2017-18 to 2023-24
A13: Debt_Model | B13: DSCR calculation - base case and three stress scenarios. Primary analytical output.
A14: Sensitivity | B14: Two-variable sensitivity table - DSCR across revenue and fertiliser cost combinations
A16: 3. KEY FINDINGS
A17: Base case | B17: DSCR of 3.06x on a cash income basis - serviceable at current conditions. However conservative DSCR using farm business profit is 0.91x - below the 1.25x threshold before any stress is applied.
A18: Scenario 1 | B18: A 30% revenue decline - consistent with the 35% fall observed in 2023-24 - renders farm cash income negative. DSCR: negative. Debt cannot be serviced from operations.
A19: Scenario 2 | B19: A 40% fertiliser cost increase - conservative relative to the 84% spike in 2021-22 - reduces DSCR to 2.08x on a cash basis. Serviceable but margin significantly compressed.
A20: Scenario 3 | B20: Combined revenue decline of 20% and fertiliser increase of 30% produces negative farm cash income. DSCR: negative.
A21: Recommendation | B21: Conditional approval - the facility is supportable at current conditions but forward outlook warrants protective covenants including forward grain sales requirements and annual DSCR covenant testing.
A23: 4. DATA SOURCES
A24: Source | B24: Data Used | F24: Date
A25: ABARES Farm Data Portal | B25: Farm financials - WA Cropping 2017-18 to 2023-24 | F25: 46143
A26: ABARES Ag Commodities Report | B26: Wheat GVP outlook, revenue forecasts 2026-27 | F26: 46082
A27: ABARES Weekly Update No.19/2026 | B27: APW wheat $403/t, canola $808/t, AUD/USD 0.71, WA seasonal conditions | F27: 46143
A28: ABARES Financial Performance Report | B28: National cropping farm benchmarks 2022-23 to 2024-25 | F28: 45839
A29: RBA Table F7 | B29: New small business lending rate: 7.01% p.a. | F29: 46082
A30: RaboResearch Farmland Outlook 2026 | B30: WA arable land median $6,330/ha - adjusted to $4,800/ha for Merredin rainfall zone | F30: 46113
A31: Rabobank Agribusiness Outlook | B31: Fertiliser market - Strait of Hormuz impact, urea price escalation | F31: 46143
A32: Bureau of Meteorology | B32: Merredin average annual rainfall 314mm | F32: Historical
A34: 5. KEY ASSUMPTIONS AND LIMITATIONS
A35: 1. Financial data reflects ABARES benchmark averages for WA cropping farms - not Mallet Ridge's actual financial records. Individual farm results will vary based on scale, debt structure, management quality, and seasonal conditions.
A36: 2. DSCR calculated using farm cash income as the primary numerator. A conservative DSCR using farm business profit of $290,580 produces 0.91x - below the 1.25x threshold in the base case. A lender applying this framework to a specific borrower would require actual financial statements.
A37: 3. Debt service calculated on straight-line amortisation at Year 1 interest - the most conservative point in the repayment schedule. Actual debt service declines in subsequent years as principal reduces.
A38: 4. Existing debt structure of the borrower is not modelled. Interest paid of $164,900 per annum implies existing debt of approximately $2.3M at current rates - but principal balance, maturity, and covenant structure are unknown from public data.
A39: 5. Livestock income from Merino wool enterprise is not captured in the ABARES cropping benchmark - conservative treatment that understates total farm revenue capacity.

Sheet Assumptions
A1: ASSUMPTIONS & DATA SOURCES - WA Broadacre Farm Debt Serviceability Analysis
A3: Variable | B3: Value | C3: Unit | D3: Tier | E3: Source | F3: Date
A4: SECTION A: ABARES FARM BENCHMARK DATA - WA Cropping, 2023–24
A5: Total cash receipts per farm | B5: 4066460 | C5: AUD per farm | D5: 1 | E5: ABARES Farm Data Portal - WA Cropping | F5: 2023-24
A6: Total cash costs per farm | B6: 3088030 | C6: AUD per farm | D6: 1 | E6: ABARES Farm Data Portal - WA Cropping | F6: 2023-24
A7: Farm cash income per farm | B7: 978440 | C7: AUD per farm | D7: 1 | E7: ABARES Farm Data Portal - WA Cropping | F7: 2023-24
A8: Farm business profit per farm | B8: 290580 | C8: AUD per farm | D8: 1 | E8: ABARES Farm Data Portal - WA Cropping | F8: 2023-24
A9: Fertiliser cost per farm | B9: 781810 | C9: AUD per farm | D9: 1 | E9: ABARES Farm Data Portal - WA Cropping | F9: 2023-24
A10: Fuel oil and grease per farm | B10: 208680 | C10: AUD per farm | D10: 1 | E10: ABARES Farm Data Portal - WA Cropping | F10: 2023-24
A11: Interest paid per farm | B11: 164900 | C11: AUD per farm | D11: 1 | E11: ABARES Farm Data Portal - WA Cropping | F11: 2023-24
A12: Total area cropped (ha) | B12: 3990 | C12: Hectares per farm | D12: 1 | E12: ABARES Farm Data Portal - WA Cropping | F12: 2023-24
A13: Wheat area sown (ha) | B13: 2064 | C13: Hectares per farm | D13: 1 | E13: ABARES Farm Data Portal - WA Cropping | F13: 2023-24
A14: Canola area sown (ha) | B14: 972 | C14: Hectares per farm | D14: 1 | E14: ABARES Farm Data Portal - WA Cropping | F14: 2023-24
A16: SECTION B: DEBT FACILITY PARAMETERS
A17: Proposed facility amount | B17: 1500000 | C17: AUD | D17: 4 | E17: Hypothetical facility - illustrative | F17: 46143
A18: Loan term (years) | B18: 7 | C18: Years | D18: 4 | E18: Standard machinery finance term - agribusiness lending | F18: Assumed
A19: Interest rate - new small business loans | B19: 0.0701 | C19: % per annum | D19: 1 | E19: RBA Table F7 - new small business loans total | F19: 46082
A20: Minimum acceptable DSCR | B20: 1.25 | C20: Ratio | D20: 4 | E20: Standard agribusiness lending covenant threshold | F20: Assumed
A21: Gross capital outlay - new machinery | B21: 1700000 | C21: AUD | D21: 3 | E21: Dealer indicative pricing - JD X9 1100 + Case IH 2160 | F21: 2025-26
A22: Trade-in credit - legacy equipment | B22: 200000 | C22: AUD | D22: 3 | E22: Dealer trade-in valuation estimate | F22: 46143
A24: SECTION C: SCENARIO SHOCK PARAMETERS
A25: Scenario 1 - Revenue decline | B25: -0.3 | C25: % change | D25: 2 | E25: Historical: receipts fell 35% in 2023-24. ABARES March 2026 forecasts wheat GVP down 13% in 2026-27 | F25: 46082
A26: Scenario 2 - Fertiliser cost increase | B26: 0.4 | C26: % change | D26: 2 | E26: Historical: fertiliser rose 84% in 2021-22. Rabobank May 2026 documents ongoing price pressure from Strait of Hormuz disruption | F26: 46143
A27: Scenario 3 - Combined revenue decline | B27: -0.2 | C27: % change | D27: 2 | E27: Simultaneous pressure scenario - ABARES 2026-27 outlook | F27: 46082
A28: Scenario 3 - Combined fertiliser increase | B28: 0.3 | C28: % change | D28: 2 | E28: Simultaneous pressure scenario - Rabobank May 2026 | F28: 46143
A30: SECTION D: CURRENT MARKET CONTEXT - FOR CREDIT MEMO REFERENCE
A31: APW wheat price FOB Port Adelaide | B31: 403 | C31: AUD per tonne | D31: 1 | E31: ABARES Weekly Update No.19/2026 | F31: 46162
A32: Canola price FOB Kwinana WA | B32: 808 | C32: AUD per tonne | D32: 1 | E32: ABARES Weekly Update No.19/2026 | F32: 46162
A33: AUD/USD exchange rate | B33: 0.71 | C33: AUD per USD | D33: 1 | E33: ABARES Weekly Update No.19/2026 | F33: 46162
A34: RBA cash rate | B34: 0.0435 | C34: % per annum | D34: 1 | E34: RBA - Cash Rate Target | F34: 46143
A35: WA arable land - state median (Rabobank) | B35: 6330 | C35: AUD per ha | D35: 2 | E35: RaboResearch Farmland Outlook 2026, p.14 | F35: 46113
A36: WA arable land - Merredin zone estimate | B36: 4800 | C36: AUD per ha | D36: 3 | E36: Adjusted for 300-400mm rainfall zone - see methodology note | F36: 46113
A37: WA grazing land - state median (Rabobank) | B37: 18600 | C37: AUD per ha | D37: 2 | E37: RaboResearch Farmland Outlook 2026, p.14 | F37: 46113
A38: WA grazing land - Merredin zone estimate | B38: 2000 | C38: AUD per ha | D38: 3 | E38: Non-arable low-rainfall grazing - discount to state median | F38: 46113
A39: Estimated total real estate value | B39: 22760000 | C39: AUD | D39: 3 | E39: Derived - land valuation table | F39: 46143
A40: LVR on proposed facility | B40: 0.054 | C40: % | D40: 3 | E40: Derived | F40: 46143
A41: Merredin average annual rainfall | B41: 314 | C41: mm | D41: 1 | E41: Bureau of Meteorology, Station 010092 | F41: Historical
A43: DISCLAIMER: Mallet Ridge Pastoral Co. is a fictional entity. This model uses ABARES benchmark data representing a representative WA cropping farm. All inputs are sourced from publicly available government and industry publications as cited above. This analysis does not constitute financial or investment advice.

Sheet Farm_Profile
A1: FARM FINANCIAL PROFILE - WA Cropping Benchmark (ABARES 2017–18 to 2023–24)
A3: SECTION A: MALLET RIDGE PASTORAL CO. - REPRESENTATIVE FARM PROFILE
A4: Item | B4: Detail | G4: Source
A5: Entity | B5: Mallet Ridge Pastoral Co. (fictional) - Edwards Agribusiness Holdings Pty Ltd | G5: Illustrative
A6: Location | B6: Shire of Merredin, Central Wheatbelt WA - approximately 256km east of Perth | G6: Shire of Merredin
A7: Annual rainfall | B7: 314 mm average - 300-400mm band | G7: BOM Merredin station
A8: Total area | B8: 5,200 ha freehold | G8: Illustrative - above ABARES WA average of 3,990 ha
A9: Arable cropping | B9: 4,200 ha - wheat, barley, canola, lupins | G9: Illustrative
A10: Livestock | B10: 600 ha - 3,200 Merino ewes | G10: Illustrative
A11: Enterprise | B11: WA winter cropping - seeded May, harvested Nov-Dec | G11: DPIRD WA
A12: Grain marketing | B12: CBH Merredin receival, Kwinana terminal | G12: CBH Group
A13: Land value estimate | B13: AUD $4,800/ha arable - total real estate $22.76M | G13: RaboResearch 2026, p.14 - adjusted for rainfall zone
A14: Ownership | B14: Multigenerational family - 46 years in operation | G14: Illustrative
A15: ABARES benchmark note | B15: Financial data reflects ABARES WA Cropping average. Mallet Ridge at 5,200 ha is above the benchmark average of 3,990 ha - ABARES data conservatively understates farm-level revenue capacity | G15: ABARES Farm Data Portal
A17: SECTION B: ABARES TIME SERIES DATA - Western Australia, Cropping Industry
A18: Variable | B18: 2017-2018 | C18: 2018-2019 | D18: 2019-2020 | E18: 2020-2021 | F18: 2021-2022 | G18: 2022-2023 | H18: 2023-2024
A19: Total cash receipts ($) | B19: 2440380 | C19: 3131030 | D19: 2753840 | E19: 3072290 | F19: 5322770 | G19: 6269290 | H19: 4066460
A20: Total cash costs ($) | B20: 1502940 | C20: 1880300 | D20: 2077580 | E20: 2205510 | F20: 3757080 | G20: 4030780 | H20: 3088030
A21: Farm cash income ($) | B21: 937440 | C21: 1250730 | D21: 676260 | E21: 866800 | F21: 1565690 | G21: 2238510 | H21: 978440
A22: Farm business profit ($) | B22: 583820 | C22: 886130 | D22: 101530 | E22: 638540 | F22: 1304150 | G22: 1893480 | H22: 290580
A23: Fertiliser ($) | B23: 276050 | C23: 367460 | D23: 464150 | E23: 444510 | F23: 816830 | G23: 1060910 | H23: 781810
A24: Fuel oil and grease ($) | B24: 127130 | C24: 153290 | D24: 159900 | E24: 148790 | F24: 254700 | G24: 297890 | H24: 208680
A25: Interest paid ($) | B25: 107300 | C25: 117150 | D25: 121880 | E25: 102030 | F25: 113040 | G25: 152560 | H25: 164900
A26: Total area cropped (ha) | B26: 3163 | C26: 3468 | D26: 3601 | E26: 3706 | F26: 4984 | G26: 4934 | H26: 3990
A27: Wheat area sown (ha) | B27: 1697 | C27: 1947 | D27: 1903 | E27: 1936 | F27: 2471 | G27: 2381 | H27: 2064
A28: Canola area sown (ha) | B28: 595 | C28: 451 | D28: 533 | E28: 511 | F28: 828 | G28: 1095 | H28: 972
A29: Source: ABARES Farm Data Portal, Western Australia, Cropping industry, 2017-18 to 2023-24. All values expressed as per-farm averages in real 2024-25 dollars. Data for years shown as financial year ending June.
A31: SECTION C: DERIVED PERFORMANCE METRICS
A32: Variable | B32: 2017-2018 | C32: 2018-2019 | D32: 2019-2020 | E32: 2020-2021 | F32: 2021-2022 | G32: 2022-2023 | H32: 2023-2024
A33: Cash margin % (farm cash income ÷ receipts) | B33: =B21/B19 -> 0.3841369 | C33: =C21/C19 -> 0.3994628 | D33: =D21/D19 -> 0.24556982 | E33: =E21/E19 -> 0.28213482 | F33: =F21/F19 -> 0.29414947 | G33: =G21/G19 -> 0.35705957 | H33: =H21/H19 -> 0.24061223
A34: Cost-to-receipt ratio (costs ÷ receipts) | B34: =B20/B19 -> 0.6158631 | C34: =C20/C19 -> 0.6005372 | D34: =D20/D19 -> 0.75443018 | E34: =E20/E19 -> 0.71787169 | F34: =F20/F19 -> 0.70585053 | G34: =G20/G19 -> 0.64294043 | H34: =H20/H19 -> 0.75939023
A35: Fertiliser as % of total costs | B35: =B23/B20 -> 0.18367333 | C35: =C23/C20 -> 0.19542626 | D35: =D23/D20 -> 0.22340897 | E35: =E23/E20 -> 0.20154522 | F35: =F23/F20 -> 0.21741086 | G35: =G23/G20 -> 0.26320216 | H35: =H23/H20 -> 0.25317435
A36: Fuel as % of total costs | B36: =B24/B20 -> 0.084587542 | C36: =C24/C20 -> 0.081524225 | D36: =D24/D20 -> 0.076964545 | E36: =E24/E20 -> 0.067462854 | F36: =F24/F20 -> 0.067792009 | G36: =G24/G20 -> 0.07390381 | H36: =H24/H20 -> 0.067577064
A37: Interest as % of total costs | B37: =B25/B20 -> 0.071393402 | C37: =C25/C20 -> 0.062303888 | D37: =D25/D20 -> 0.058664408 | E37: =E25/E20 -> 0.046261409 | F37: =F25/F20 -> 0.030087195 | G37: =G25/G20 -> 0.037848754 | H37: =H25/H20 -> 0.05339974
A38: Total cash receipts per hectare ($/ha) | B38: =B19/B26 -> 771.53968 | C38: =C19/C26 -> 902.83449 | D38: =D19/D26 -> 764.74313 | E38: =E19/E26 -> 829.00432 | F38: =F19/F26 -> 1067.9715 | G38: =G19/G26 -> 1270.6303 | H38: =H19/H26 -> 1019.1629
A39: Total cash costs per hectare ($/ha) | B39: =B20/B26 -> 475.16282 | C39: =C20/C26 -> 542.1857 | D39: =D20/D26 -> 576.94529 | E39: =E20/E26 -> 595.11873 | F39: =F20/F26 -> 753.82825 | G39: =G20/G26 -> 816.9396 | H39: =H20/H26 -> 773.94236
A40: All derived metrics calculated from ABARES Farm Data Portal data. Percentage figures expressed as one decimal place.
A42: SECTION D: KEY OBSERVATIONS - 2023–24 BASE YEAR
A43: 1. Farm cash income fell 56% from the 2022-23 peak -$2,238,510 to $978,440 in 2023-24, driven by a 35% fall in total cash receipts while costs fell only 23%.
A44: 2. Fertiliser now represents 25.3% of total cash costs in 2023-24, up from 18.4% in 2017-18 - reflecting structural cost escalation in the farm input base.
...

Sheet Debt_Model
A1: DEBT SERVICEABILITY MODEL - Mallet Ridge Pastoral Co. - $1.5M Machinery Facility
A3: Item | B3: Base Case | C3: Scenario 1 - Revenue Decline | D3: Scenario 2 - Input Cost Spike | E3: Scenario 3 - Combined Shock
A4: SECTION A: FARM REVENUE
A5: Total cash receipts ($) | B5: =Assumptions!B5 -> 4066460 | C5: =B5*(1+Assumptions!B25) -> 2846522 | D5: =B5 -> 4066460 | E5: =B5*(1+Assumptions!B27) -> 3253168
A7: SECTION B: FARM COSTS
A8: Fertiliser ($) | B8: =Assumptions!B9 -> 781810 | C8: =B8 -> 781810 | D8: =B8*(1+Assumptions!B26) -> 1094534 | E8: =B8*(1+Assumptions!B28) -> 1016353
A9: Fuel oil and grease ($) | B9: =Assumptions!B10 -> 208680 | C9: =B9 -> 208680 | D9: =B9 -> 208680 | E9: =B9 -> 208680
A10: Interest paid - existing debt ($) | B10: =Assumptions!B11 -> 164900 | C10: =B10 -> 164900 | D10: =B10 -> 164900 | E10: =B10 -> 164900
A11: Other costs | B11: =Assumptions!B6-Assumptions!B9-Assumptions!B10-Assumptions!B11 -> 1932640 | C11: =B11 -> 1932640 | D11: =B11 -> 1932640 | E11: =B11 -> 1932640
A12: Total cash costs ($) | B12: =SUM(B8:B11) -> 3088030 | C12: =SUM(C8:C11) -> 3088030 | D12: =SUM(D8:D11) -> 3400754 | E12: =SUM(E8:E11) -> 3322573
A14: SECTION C: FARM CASH INCOME
A15: Farm cash income ($) | B15: =B5-B12 -> 978430 | C15: =C5-C12 -> -241508 | D15: =D5-D12 -> 665706 | E15: =E5-E12 -> -69405
A16: Cash margin % (income ÷ receipts) | B16: =B15/B5 -> 0.24060977 | C16: =IF(C5>0,C15/C5,"N/A") -> -0.084843188 | D16: =D15/D5 -> 0.16370652 | E16: =IF(E5>0,E15/E5,"N/A") -> -0.021334588
A18: SECTION D: DEBT SERVICE CALCULATION - $1.5M FACILITY, 7 YEARS @ 7.01% P.A.
A19: Annual principal repayment ($) | B19: =Assumptions!B17/Assumptions!B18 -> 214285.71 | C19: =B19 -> 214285.71 | D19: =B19 -> 214285.71 | E19: =B19 -> 214285.71
A20: Annual interest on new facility - Year 1 ($) | B20: =Assumptions!B17*Assumptions!B19 -> 105150 | C20: =B20 -> 105150 | D20: =B20 -> 105150 | E20: =B20 -> 105150
A21: Total annual debt service - new facility ($) | B21: =B19+B20 -> 319435.71 | C21: =B21 -> 319435.71 | D21: =B21 -> 319435.71 | E21: =B21 -> 319435.71
A23: SECTION E: DEBT SERVICE COVERAGE RATIO (DSCR)
A24: DSCR (farm cash income ÷ total debt service) | B24: =B15/B21 -> 3.062995 | C24: =IF(C15>0,C15/C21,"< 0") -> < 0 | D24: =D15/D21 -> 2.0840062 | E24: =IF(E15>0,E15/E21,"< 0") -> < 0
A25: Farm business profit - estimated ($) | B25: =Assumptions!B8 -> 290580 | C25: =IF(ISNUMBER(C15),C15*$B$40,"N/A") -> -71723.759 | D25: =IF(ISNUMBER(D15),D15*$B$40,"N/A") -> 197703.33 | E25: =IF(ISNUMBER(E15),E15*$B$40,"N/A") -> -20612.102
A26: DSCR - Conservative basis (farm business profit ÷ debt service) | B26: =IF(B25>0,B25/B21,"< 0") -> 0.9096666 | C26: =IF(ISNUMBER(C25),IF(C25>0,C25/C21,"< 0"),"N/A") -> < 0 | D26: =IF(D25>0,D25/D21,"< 0") -> 0.61891431 | E26: =IF(ISNUMBER(E25),IF(E25>0,E25/E21,"< 0"),"N/A") -> < 0
A27: Minimum acceptable DSCR threshold | B27: =Assumptions!B20 -> 1.25 | C27: =Assumptions!B20 -> 1.25 | D27: =Assumptions!B20 -> 1.25 | E27: =Assumptions!B20 -> 1.25
A28: DSCR headroom above 1.25x (cash basis) | B28: =B24-B27 -> 1.812995 | C28: =IF(ISNUMBER(C24),C24-C27,"N/A") -> N/A | D28: =D24-D27 -> 0.83400617 | E28: =IF(ISNUMBER(E24),E24-E27,"N/A") -> N/A
A30: SECTION F: CREDIT ASSESSMENT VERDICT
A31: Verdict | B31: Conditional Approval | C31: Decline - Cash Flow Negative | D31: Conditional Approval | E31: Decline - Cash Flow Negative
A32: Rationale | B32: DSCR of 3.06x is comfortable but forward outlook warrants protective covenants | C32: A 30% revenue decline renders farm cash-flow negative before debt service | D32: DSCR remains above threshold but fertiliser pressure warrants monitoring | E32: Simultaneous revenue and cost pressure produces negative farm cash income
A34: SECTION G: SCENARIO JUSTIFICATION
A35: Scenario 1 (Revenue −30%): Anchored in historical data - total cash receipts fell 35% between 2022-23 and 2023-24 (ABARES Farm Data Portal). ABARES March 2026 Agricultural Commodities Report forecasts wheat GVP to fall a further 13% in 2026-27. Dry conditions across WA cropping regions documented in ABARES Weekly Update 21 May 2026 present additional downside risk to 2026-27 production.
A36: Scenario 2 (Fertiliser +40%): Anchored in historical data - fertiliser costs rose 84% between 2020-21 and 2021-22 (ABARES Farm Data Portal). Rabobank Agribusiness Outlook May 2026 documents ongoing fertiliser price escalation driven by Strait of Hormuz disruption, with Middle East urea spot prices rising 8% month-on-month in April 2026 and phosphate prices rising 20% month-on-month.
A37: Scenario 3 (Combined −20% revenue, +30% fertiliser): Tests simultaneous margin compression consistent with the 2026-27 outlook described in ABARES March 2026 - lower crop prices and higher input costs occurring together. This scenario reflects the stagflationary environment Rabobank identifies as the key risk for Australian broadacre producers in 2026.
A39: HELPER - DO NOT EDIT
A40: Profit-to-income ratio | B40: =Assumptions!B8/Assumptions!B7 -> 0.29698295

Sheet Sensitivity
A1: SENSITIVITY ANALYSIS - DSCR UNDER COMBINED REVENUE AND FERTILISER COST SCENARIOS
C3: ← Revenue Change →
C4: -0.4 | D4: =C4+5% -> -0.35 | E4: =D4+5% -> -0.3 | F4: =E4+5% -> -0.25 | G4: =F4+5% -> -0.2 | H4: =G4+5% -> -0.15 | I4: =H4+5% -> -0.1 | J4: =I4+5% -> -0.05 | K4: =J4+5% -> -6.9388939e-17 | ... M4: =L4+5% -> 0.1
A5: ↑ Fertiliser Cost Change ↓ | B5: 0.6 | C5: =(($P$6*(1+C$4))-(($P$7*(1+$B5))+$P$8+$P$9+$P$10))/$P$11 -> -3.4975425 | D5: =(($P$6*(1+D$4))-(($P$7*(1+$B5))+$P$8+$P$9+$P$10))/$P$11 -> -2.8610358 | E5: =(($P$6*(1+E$4))-(($P$7*(1+$B5))+$P$8+$P$9+$P$10))/$P$11 -> -2.224529 | F5: =(($P$6*(1+F$4))-(($P$7*(1+$B5))+$P$8+$P$9+$P$10))/$P$11 -> -1.5880222 | G5: =(($P$6*(1+G$4))-(($P$7*(1+$B5))+$P$8+$P$9+$P$10))/$P$11 -> -0.9515154 | H5: =(($P$6*(1+H$4))-(($P$7*(1+$B5))+$P$8+$P$9+$P$10))/$P$11 -> -0.31500861 | I5: =(($P$6*(1+I$4))-(($P$7*(1+$B5))+$P$8+$P$9+$P$10))/$P$11 -> 0.32149818 | J5: =(($P$6*(1+J$4))-(($P$7*(1+$B5))+$P$8+$P$9+$P$10))/$P$11 -> 0.95800496 | ... M5: =(($P$6*(1+M$4))-(($P$7*(1+$B5))+$P$8+$P$9+$P$10))/$P$11 -> 2.8675253 | O5: HELPER
B6: =B5-10% -> 0.5 | C6: =(($P$6*(1+C$4))-(($P$7*(1+$B6))+$P$8+$P$9+$P$10))/$P$11 -> -3.2527953 | D6: =(($P$6*(1+D$4))-(($P$7*(1+$B6))+$P$8+$P$9+$P$10))/$P$11 -> -2.6162885 | E6: =(($P$6*(1+E$4))-(($P$7*(1+$B6))+$P$8+$P$9+$P$10))/$P$11 -> -1.9797818 | F6: =(($P$6*(1+F$4))-(($P$7*(1+$B6))+$P$8+$P$9+$P$10))/$P$11 -> -1.343275 | G6: =(($P$6*(1+G$4))-(($P$7*(1+$B6))+$P$8+$P$9+$P$10))/$P$11 -> -0.70676818 | H6: =(($P$6*(1+H$4))-(($P$7*(1+$B6))+$P$8+$P$9+$P$10))/$P$11 -> -0.070261398 | I6: =(($P$6*(1+I$4))-(($P$7*(1+$B6))+$P$8+$P$9+$P$10))/$P$11 -> 0.56624539 | J6: =(($P$6*(1+J$4))-(($P$7*(1+$B6))+$P$8+$P$9+$P$10))/$P$11 -> 1.2027522 | ... M6: =(($P$6*(1+M$4))-(($P$7*(1+$B6))+$P$8+$P$9+$P$10))/$P$11 -> 3.1122725 | O6: Base receipts | P6: =Assumptions!B5 -> 4066460
B7: =B6-10% -> 0.4 | C7: =(($P$6*(1+C$4))-(($P$7*(1+$B7))+$P$8+$P$9+$P$10))/$P$11 -> -3.0080481 | D7: =(($P$6*(1+D$4))-(($P$7*(1+$B7))+$P$8+$P$9+$P$10))/$P$11 -> -2.3715413 | E7: =(($P$6*(1+E$4))-(($P$7*(1+$B7))+$P$8+$P$9+$P$10))/$P$11 -> -1.7350345 | F7: =(($P$6*(1+F$4))-(($P$7*(1+$B7))+$P$8+$P$9+$P$10))/$P$11 -> -1.0985278 | G7: =(($P$6*(1+G$4))-(($P$7*(1+$B7))+$P$8+$P$9+$P$10))/$P$11 -> -0.46202097 | H7: =(($P$6*(1+H$4))-(($P$7*(1+$B7))+$P$8+$P$9+$P$10))/$P$11 -> 0.17448581 | I7: =(($P$6*(1+I$4))-(($P$7*(1+$B7))+$P$8+$P$9+$P$10))/$P$11 -> 0.8109926 | J7: =(($P$6*(1+J$4))-(($P$7*(1+$B7))+$P$8+$P$9+$P$10))/$P$11 -> 1.4474994 | ... M7: =(($P$6*(1+M$4))-(($P$7*(1+$B7))+$P$8+$P$9+$P$10))/$P$11 -> 3.3570197 | O7: Base fertiliser | P7: =Assumptions!B9 -> 781810
B8: =B7-10% -> 0.3 | C8: =(($P$6*(1+C$4))-(($P$7*(1+$B8))+$P$8+$P$9+$P$10))/$P$11 -> -2.7633009 | D8: =(($P$6*(1+D$4))-(($P$7*(1+$B8))+$P$8+$P$9+$P$10))/$P$11 -> -2.1267941 | E8: =(($P$6*(1+E$4))-(($P$7*(1+$B8))+$P$8+$P$9+$P$10))/$P$11 -> -1.4902873 | F8: =(($P$6*(1+F$4))-(($P$7*(1+$B8))+$P$8+$P$9+$P$10))/$P$11 -> -0.85378055 | G8: =(($P$6*(1+G$4))-(($P$7*(1+$B8))+$P$8+$P$9+$P$10))/$P$11 -> -0.21727376 | H8: =(($P$6*(1+H$4))-(($P$7*(1+$B8))+$P$8+$P$9+$P$10))/$P$11 -> 0.41923302 | I8: =(($P$6*(1+I$4))-(($P$7*(1+$B8))+$P$8+$P$9+$P$10))/$P$11 -> 1.0557398 | J8: =(($P$6*(1+J$4))-(($P$7*(1+$B8))+$P$8+$P$9+$P$10))/$P$11 -> 1.6922466 | ... M8: =(($P$6*(1+M$4))-(($P$7*(1+$B8))+$P$8+$P$9+$P$10))/$P$11 -> 3.601767 | O8: Base fuel | P8: =Assumptions!B10 -> 208680
B9: =B8-10% -> 0.2 | C9: =(($P$6*(1+C$4))-(($P$7*(1+$B9))+$P$8+$P$9+$P$10))/$P$11 -> -2.5185537 | D9: =(($P$6*(1+D$4))-(($P$7*(1+$B9))+$P$8+$P$9+$P$10))/$P$11 -> -1.8820469 | E9: =(($P$6*(1+E$4))-(($P$7*(1+$B9))+$P$8+$P$9+$P$10))/$P$11 -> -1.2455401 | F9: =(($P$6*(1+F$4))-(($P$7*(1+$B9))+$P$8+$P$9+$P$10))/$P$11 -> -0.60903334 | G9: =(($P$6*(1+G$4))-(($P$7*(1+$B9))+$P$8+$P$9+$P$10))/$P$11 -> 0.027473446 | H9: =(($P$6*(1+H$4))-(($P$7*(1+$B9))+$P$8+$P$9+$P$10))/$P$11 -> 0.66398023 | I9: =(($P$6*(1+I$4))-(($P$7*(1+$B9))+$P$8+$P$9+$P$10))/$P$11 -> 1.300487 | J9: =(($P$6*(1+J$4))-(($P$7*(1+$B9))+$P$8+$P$9+$P$10))/$P$11 -> 1.9369938 | ... M9: =(($P$6*(1+M$4))-(($P$7*(1+$B9))+$P$8+$P$9+$P$10))/$P$11 -> 3.8465142 | O9: Base interest | P9: =Assumptions!B11 -> 164900
B10: =B9-10% -> 0.1 | C10: =(($P$6*(1+C$4))-(($P$7*(1+$B10))+$P$8+$P$9+$P$10))/$P$11 -> -2.2738065 | D10: =(($P$6*(1+D$4))-(($P$7*(1+$B10))+$P$8+$P$9+$P$10))/$P$11 -> -1.6372997 | E10: =(($P$6*(1+E$4))-(($P$7*(1+$B10))+$P$8+$P$9+$P$10))/$P$11 -> -1.0007929 | F10: =(($P$6*(1+F$4))-(($P$7*(1+$B10))+$P$8+$P$9+$P$10))/$P$11 -> -0.36428613 | G10: =(($P$6*(1+G$4))-(($P$7*(1+$B10))+$P$8+$P$9+$P$10))/$P$11 -> 0.27222066 | H10: =(($P$6*(1+H$4))-(($P$7*(1+$B10))+$P$8+$P$9+$P$10))/$P$11 -> 0.90872744 | I10: =(($P$6*(1+I$4))-(($P$7*(1+$B10))+$P$8+$P$9+$P$10))/$P$11 -> 1.5452342 | J10: =(($P$6*(1+J$4))-(($P$7*(1+$B10))+$P$8+$P$9+$P$10))/$P$11 -> 2.181741 | ... M10: =(($P$6*(1+M$4))-(($P$7*(1+$B10))+$P$8+$P$9+$P$10))/$P$11 -> 4.0912614 | O10: Base other costs | P10: =Assumptions!B6-Assumptions!B9-Assumptions!B10-Assumptions!B11 -> 1932640
B11: =B10-10% -> 0 | C11: =(($P$6*(1+C$4))-(($P$7*(1+$B11))+$P$8+$P$9+$P$10))/$P$11 -> -2.0290593 | D11: =(($P$6*(1+D$4))-(($P$7*(1+$B11))+$P$8+$P$9+$P$10))/$P$11 -> -1.3925525 | E11: =(($P$6*(1+E$4))-(($P$7*(1+$B11))+$P$8+$P$9+$P$10))/$P$11 -> -0.75604571 | F11: =(($P$6*(1+F$4))-(($P$7*(1+$B11))+$P$8+$P$9+$P$10))/$P$11 -> -0.11953892 | G11: =(($P$6*(1+G$4))-(($P$7*(1+$B11))+$P$8+$P$9+$P$10))/$P$11 -> 0.51696787 | H11: =(($P$6*(1+H$4))-(($P$7*(1+$B11))+$P$8+$P$9+$P$10))/$P$11 -> 1.1534747 | I11: =(($P$6*(1+I$4))-(($P$7*(1+$B11))+$P$8+$P$9+$P$10))/$P$11 -> 1.7899814 | J11: =(($P$6*(1+J$4))-(($P$7*(1+$B11))+$P$8+$P$9+$P$10))/$P$11 -> 2.4264882 | ... M11: =(($P$6*(1+M$4))-(($P$7*(1+$B11))+$P$8+$P$9+$P$10))/$P$11 -> 4.3360086 | O11: Debt service | P11: =Debt_Model!B21 -> 319435.71
B12: =B11-10% -> -0.1 | C12: =(($P$6*(1+C$4))-(($P$7*(1+$B12))+$P$8+$P$9+$P$10))/$P$11 -> -1.7843121 | D12: =(($P$6*(1+D$4))-(($P$7*(1+$B12))+$P$8+$P$9+$P$10))/$P$11 -> -1.1478053 | E12: =(($P$6*(1+E$4))-(($P$7*(1+$B12))+$P$8+$P$9+$P$10))/$P$11 -> -0.5112985 | F12: =(($P$6*(1+F$4))-(($P$7*(1+$B12))+$P$8+$P$9+$P$10))/$P$11 -> 0.12520829 | G12: =(($P$6*(1+G$4))-(($P$7*(1+$B12))+$P$8+$P$9+$P$10))/$P$11 -> 0.76171508 | H12: =(($P$6*(1+H$4))-(($P$7*(1+$B12))+$P$8+$P$9+$P$10))/$P$11 -> 1.3982219 | I12: =(($P$6*(1+I$4))-(($P$7*(1+$B12))+$P$8+$P$9+$P$10))/$P$11 -> 2.0347287 | J12: =(($P$6*(1+J$4))-(($P$7*(1+$B12))+$P$8+$P$9+$P$10))/$P$11 -> 2.6712354 | ... M12: =(($P$6*(1+M$4))-(($P$7*(1+$B12))+$P$8+$P$9+$P$10))/$P$11 -> 4.5807558
B13: =B12-10% -> -0.2 | C13: =(($P$6*(1+C$4))-(($P$7*(1+$B13))+$P$8+$P$9+$P$10))/$P$11 -> -1.5395649 | D13: =(($P$6*(1+D$4))-(($P$7*(1+$B13))+$P$8+$P$9+$P$10))/$P$11 -> -0.90305807 | E13: =(($P$6*(1+E$4))-(($P$7*(1+$B13))+$P$8+$P$9+$P$10))/$P$11 -> -0.26655128 | F13: =(($P$6*(1+F$4))-(($P$7*(1+$B13))+$P$8+$P$9+$P$10))/$P$11 -> 0.3699555 | G13: =(($P$6*(1+G$4))-(($P$7*(1+$B13))+$P$8+$P$9+$P$10))/$P$11 -> 1.0064623 | H13: =(($P$6*(1+H$4))-(($P$7*(1+$B13))+$P$8+$P$9+$P$10))/$P$11 -> 1.6429691 | I13: =(($P$6*(1+I$4))-(($P$7*(1+$B13))+$P$8+$P$9+$P$10))/$P$11 -> 2.2794759 | J13: =(($P$6*(1+J$4))-(($P$7*(1+$B13))+$P$8+$P$9+$P$10))/$P$11 -> 2.9159826 | ... M13: =(($P$6*(1+M$4))-(($P$7*(1+$B13))+$P$8+$P$9+$P$10))/$P$11 -> 4.825503
B15: Green cell + text | D15: DSCR ≥ 1.25x - Serviceable
B16: Orange cell + text | D16: 0 ≤ DSCR < 1.25x - Below minimum threshold
B17: Dark red cell + text | D17: DSCR < 0 - Cash flow negative before debt service
B19: Scenario | D19: Condition | G19: DSCR
B20: Scenario 1 - Revenue decline | D20: Revenue -30%, Fertiliser 0% | G20: =E11 -> -0.75604571
B21: Scenario 2 - Fertiliser spike | D21: Revenue 0%, Fertiliser +40% | G21: =K7 -> 2.0840062
B22: Scenario 3 - Combined shock | D22: Revenue -20%, Fertiliser +30% | G22: =G8 -> -0.21727376
